<?xml version="1.0" ?>
<robot name="pelican_pedal_bike">
  <material name="rubber_black"><color rgba="0.003 0.003 0.003 1" /></material>
  <material name="rim_silver"><color rgba="0.70 0.72 0.70 1" /></material>
  <material name="spoke_steel"><color rgba="0.82 0.84 0.82 1" /></material>
  <material name="frame_blue"><color rgba="0.05 0.28 0.75 1" /></material>
  <material name="seat_brown"><color rgba="0.28 0.12 0.05 1" /></material>
  <material name="pelican_white"><color rgba="0.96 0.95 0.88 1" /></material>
  <material name="wing_gray"><color rgba="0.66 0.68 0.64 1" /></material>
  <material name="feather_dark"><color rgba="0.08 0.08 0.075 1" /></material>
  <material name="bill_yellow"><color rgba="1.00 0.78 0.26 1" /></material>
  <material name="pouch_orange"><color rgba="0.95 0.45 0.12 1" /></material>
  <material name="leg_orange"><color rgba="0.98 0.50 0.12 1" /></material>
  <material name="eye_black"><color rgba="0.0 0.0 0.0 1" /></material>
  <link name="world">
  </link>
  <link name="bike_frame_link">
    <inertial>
      <origin xyz="0 0 0" rpy="0 0 0" />
      <mass value="0.7" />
      <inertia ixx="7e-05" ixy="0" ixz="0" iyy="7e-05" iyz="0" izz="7e-05" />
    </inertial>
    <visual name="seat_tube">
      <origin xyz="-0.0075 0 0.0675" rpy="0.385157506 0 -1.57079633" />
      <geometry>
        <mesh filename="meshes/unit_cylinder_z.stl" scale="0.0046 0.0046 0.0399249296" />
      </geometry>
      <material name="frame_blue" />
    </visual>
    <visual name="top_tube">
      <origin xyz="0.0115 0 0.087" rpy="1.53307837 0 1.57079633" />
      <geometry>
        <mesh filename="meshes/unit_cylinder_z.stl" scale="0.0042 0.0042 0.0530377224" />
      </geometry>
      <material name="frame_blue" />
    </visual>
    <visual name="down_tube">
      <origin xyz="0.0215 0 0.0575" rpy="1.19430599 0 1.57079633" />
      <geometry>
        <mesh filename="meshes/unit_cylinder_z.stl" scale="0.005 0.005 0.0462385121" />
      </geometry>
      <material name="frame_blue" />
    </visual>
    <visual name="head_tube">
      <origin xyz="0.0405 0 0.077" rpy="0.223476601 0 -1.57079633" />
      <geometry>
        <mesh filename="meshes/unit_cylinder_z.stl" scale="0.0052 0.0052 0.0225610283" />
      </geometry>
      <material name="frame_blue" />
    </visual>
    <visual name="left_chain_stay">
      <origin xyz="-0.0275 -0.004 0.0465" rpy="1.66145621 0 -1.57079633" />
      <geometry>
        <mesh filename="meshes/unit_cylinder_z.stl" scale="0.0032 0.0032 0.0552268051" />
      </geometry>
      <material name="frame_blue" />
    </visual>
    <visual name="right_chain_stay">
      <origin xyz="-0.0275 0.004 0.0465" rpy="1.66145621 0 -1.57079633" />
      <geometry>
        <mesh filename="meshes/unit_cylinder_z.stl" scale="0.0032 0.0032 0.0552268051" />
      </geometry>
      <material name="frame_blue" />
    </visual>
    <visual name="left_seat_stay">
      <origin xyz="-0.035 -0.004 0.065" rpy="2.3805799 0 -1.57079633" />
      <geometry>
        <mesh filename="meshes/unit_cylinder_z.stl" scale="0.003 0.003 0.058" />
      </geometry>
      <material name="frame_blue" />
    </visual>
    <visual name="right_seat_stay">
      <origin xyz="-0.035 0.004 0.065" rpy="2.3805799 0 -1.57079633" />
      <geometry>
        <mesh filename="meshes/unit_cylinder_z.stl" scale="0.003 0.003 0.058" />
      </geometry>
      <material name="frame_blue" />
    </visual>
    <visual name="front_left_fork_blade">
      <origin xyz="0.049 -0.004 0.055" rpy="2.64224593 0 1.57079633" />
      <geometry>
        <mesh filename="meshes/unit_cylinder_z.stl" scale="0.0032 0.0032 0.0250599282" />
      </geometry>
      <material name="frame_blue" />
    </visual>
    <visual name="front_right_fork_blade">
      <origin xyz="0.049 0.004 0.055" rpy="2.64224593 0 1.57079633" />
      <geometry>
        <mesh filename="meshes/unit_cylinder_z.stl" scale="0.0032 0.0032 0.0250599282" />
      </geometry>
      <material name="frame_blue" />
    </visual>
    <visual name="handlebar_stem">
      <origin xyz="0.051 0 0.0945" rpy="1.10714872 0 1.57079633" />
      <geometry>
        <mesh filename="meshes/unit_cylinder_z.stl" scale="0.0034 0.0034 0.0290688837" />
      </geometry>
      <material name="frame_blue" />
    </visual>
    <visual name="handlebar_crossbar">
      <origin xyz="0.064 0 0.101" rpy="1.57079633 0 3.14159265" />
      <geometry>
        <mesh filename="meshes/unit_cylinder_z.stl" scale="0.0032 0.0032 0.044" />
      </geometry>
      <material name="frame_blue" />
    </visual>
    <visual name="brown_saddle">
      <origin xyz="-0.02 0 0.097" rpy="0 0 0" />
      <geometry>
        <mesh filename="meshes/unit_box.stl" scale="0.024 0.017 0.005" />
      </geometry>
      <material name="seat_brown" />
    </visual>
    <visual name="left_black_grip">
      <origin xyz="0.064 -0.024 0.101" rpy="0 0 0" />
      <geometry>
        <mesh filename="meshes/unit_box.stl" scale="0.008 0.006 0.006" />
      </geometry>
      <material name="rubber_black" />
    </visual>
    <visual name="right_black_grip">
      <origin xyz="0.064 0.024 0.101" rpy="0 0 0" />
      <geometry>
        <mesh filename="meshes/unit_box.stl" scale="0.008 0.006 0.006" />
      </geometry>
      <material name="rubber_black" />
    </visual>
    <collision>
      <origin xyz="0 0 0.065" rpy="0 0 0" />
      <geometry><box size="0.14 0.06 0.09" /></geometry>
    </collision>
  </link>
  <link name="rear_wheel_link">
    <inertial>
      <origin xyz="0 0 0" rpy="0 0 0" />
      <mass value="0.18" />
      <inertia ixx="1.8e-05" ixy="0" ixz="0" iyy="1.8e-05" iyz="0" izz="1.8e-05" />
    </inertial>
    <visual name="rear_wheel_black_tire">
      <origin xyz="0 0 0" rpy="-1.57079633 0 0" />
      <geometry>
        <mesh filename="meshes/unit_torus_z.stl" scale="0.088 0.088 0.088" />
      </geometry>
      <material name="rubber_black" />
    </visual>
    <visual name="rear_wheel_silver_rim">
      <origin xyz="0 0 0" rpy="-1.57079633 0 0" />
      <geometry>
        <mesh filename="meshes/unit_torus_z.stl" scale="0.066 0.066 0.066" />
      </geometry>
      <material name="rim_silver" />
    </visual>
    <visual name="rear_wheel_hub">
      <origin xyz="0 0 0" rpy="1.57079633 0 3.14159265" />
      <geometry>
        <mesh filename="meshes/unit_cylinder_z.stl" scale="0.008 0.008 0.016" />
      </geometry>
      <material name="rim_silver" />
    </visual>
    <visual name="rear_wheel_spoke_01">
      <origin xyz="0.015 0.00075 0" rpy="1.57079633 0 1.52083793" />
      <geometry>
        <mesh filename="meshes/unit_cylinder_z.stl" scale="0.001 0.001 0.0300374766" />
      </geometry>
      <material name="spoke_steel" />
    </visual>
    <visual name="rear_wheel_spoke_02">
      <origin xyz="0.013858193 -0.00075 0.00574025149" rpy="1.17861399 0 1.62486319" />
      <geometry>
        <mesh filename="meshes/unit_cylinder_z.stl" scale="0.001 0.001 0.0300374766" />
      </geometry>
      <material name="spoke_steel" />
    </visual>
    <visual name="rear_wheel_spoke_03">
      <origin xyz="0.0106066017 0.00075 0.0106066017" rpy="0.786645047 0 1.50020315" />
      <geometry>
        <mesh filename="meshes/unit_cylinder_z.stl" scale="0.001 0.001 0.0300374766" />
      </geometry>
      <material name="spoke_steel" />
    </visual>
    <visual name="rear_wheel_spoke_04">
      <origin xyz="0.00574025149 -0.00075 0.013858193" rpy="-0.392182339 -0.0540668651 -1.57079633" />
      <geometry>
        <mesh filename="meshes/unit_cylinder_z.stl" scale="0.001 0.001 0.0300374766" />
      </geometry>
      <material name="spoke_steel" />
    </visual>
    <visual name="rear_wheel_spoke_05">
      <origin xyz="0 0.00075 0.015" rpy="0 0.0499583957 -1.57079633" />
      <geometry>
        <mesh filename="meshes/unit_cylinder_z.stl" scale="0.001 0.001 0.0300374766" />
      </geometry>
      <material name="spoke_steel" />
    </visual>
    <visual name="rear_wheel_spoke_06">
      <origin xyz="-0.00574025149 -0.00075 0.013858193" rpy="0.392182339 -0.0540668651 -1.57079633" />
      <geometry>
        <mesh filename="meshes/unit_cylinder_z.stl" scale="0.001 0.001 0.0300374766" />
      </geometry>
      <material name="spoke_steel" />
    </visual>
    <visual name="rear_wheel_spoke_07">
      <origin xyz="-0.0106066017 0.00075 0.0106066017" rpy="0.786645047 0 -1.50020315" />
      <geometry>
        <mesh filename="meshes/unit_cylinder_z.stl" scale="0.001 0.001 0.0300374766" />
      </geometry>
      <material name="spoke_steel" />
    </visual>
    <visual name="rear_wheel_spoke_08">
      <origin xyz="-0.013858193 -0.00075 0.00574025149" rpy="1.17861399 0 -1.62486319" />
      <geometry>
        <mesh filename="meshes/unit_cylinder_z.stl" scale="0.001 0.001 0.0300374766" />
      </geometry>
      <material name="spoke_steel" />
    </visual>
    <visual name="rear_wheel_spoke_09">
      <origin xyz="-0.015 0.00075 0" rpy="1.57079633 0 -1.52083793" />
      <geometry>
        <mesh filename="meshes/unit_cylinder_z.stl" scale="0.001 0.001 0.0300374766" />
      </geometry>
      <material name="spoke_steel" />
    </visual>
    <visual name="rear_wheel_spoke_10">
      <origin xyz="-0.013858193 -0.00075 -0.00574025149" rpy="1.96297867 0 -1.62486319" />
      <geometry>
        <mesh filename="meshes/unit_cylinder_z.stl" scale="0.001 0.001 0.0300374766" />
      </geometry>
      <material name="spoke_steel" />
    </visual>
    <visual name="rear_wheel_spoke_11">
      <origin xyz="-0.0106066017 0.00075 -0.0106066017" rpy="2.35494761 0 -1.50020315" />
      <geometry>
        <mesh filename="meshes/unit_cylinder_z.stl" scale="0.001 0.001 0.0300374766" />
      </geometry>
      <material name="spoke_steel" />
    </visual>
    <visual name="rear_wheel_spoke_12">
      <origin xyz="-0.00574025149 -0.00075 -0.013858193" rpy="-2.74941031 -0.0540668651 1.57079633" />
      <geometry>
        <mesh filename="meshes/unit_cylinder_z.stl" scale="0.001 0.001 0.0300374766" />
      </geometry>
      <material name="spoke_steel" />
    </visual>
    <visual name="rear_wheel_spoke_13">
      <origin xyz="0 0.00075 -0.015" rpy="-3.14159265 0.0499583957 1.57079633" />
      <geometry>
        <mesh filename="meshes/unit_cylinder_z.stl" scale="0.001 0.001 0.0300374766" />
      </geometry>
      <material name="spoke_steel" />
    </visual>
    <visual name="rear_wheel_spoke_14">
      <origin xyz="0.00574025149 -0.00075 -0.013858193" rpy="2.74941031 -0.0540668651 1.57079633" />
      <geometry>
        <mesh filename="meshes/unit_cylinder_z.stl" scale="0.001 0.001 0.0300374766" />
      </geometry>
      <material name="spoke_steel" />
    </visual>
    <visual name="rear_wheel_spoke_15">
      <origin xyz="0.0106066017 0.00075 -0.0106066017" rpy="2.35494761 0 1.50020315" />
      <geometry>
        <mesh filename="meshes/unit_cylinder_z.stl" scale="0.001 0.001 0.0300374766" />
      </geometry>
      <material name="spoke_steel" />
    </visual>
    <visual name="rear_wheel_spoke_16">
      <origin xyz="0.013858193 -0.00075 -0.00574025149" rpy="1.96297867 0 1.62486319" />
      <geometry>
        <mesh filename="meshes/unit_cylinder_z.stl" scale="0.001 0.001 0.0300374766" />
      </geometry>
      <material name="spoke_steel" />
    </visual>
    <collision>
      <origin xyz="0 0 0" rpy="-1.57079633 0 0" />
      <geometry><cylinder radius="0.044" length="0.012" /></geometry>
    </collision>
  </link>
  <link name="front_wheel_link">
    <inertial>
      <origin xyz="0 0 0" rpy="0 0 0" />
      <mass value="0.18" />
      <inertia ixx="1.8e-05" ixy="0" ixz="0" iyy="1.8e-05" iyz="0" izz="1.8e-05" />
    </inertial>
    <visual name="front_wheel_black_tire">
      <origin xyz="0 0 0" rpy="-1.57079633 0 0" />
      <geometry>
        <mesh filename="meshes/unit_torus_z.stl" scale="0.088 0.088 0.088" />
      </geometry>
      <material name="rubber_black" />
    </visual>
    <visual name="front_wheel_silver_rim">
      <origin xyz="0 0 0" rpy="-1.57079633 0 0" />
      <geometry>
        <mesh filename="meshes/unit_torus_z.stl" scale="0.066 0.066 0.066" />
      </geometry>
      <material name="rim_silver" />
    </visual>
    <visual name="front_wheel_hub">
      <origin xyz="0 0 0" rpy="1.57079633 0 3.14159265" />
      <geometry>
        <mesh filename="meshes/unit_cylinder_z.stl" scale="0.008 0.008 0.016" />
      </geometry>
      <material name="rim_silver" />
    </visual>
    <visual name="front_wheel_spoke_01">
      <origin xyz="0.015 0.00075 0" rpy="1.57079633 0 1.52083793" />
      <geometry>
        <mesh filename="meshes/unit_cylinder_z.stl" scale="0.001 0.001 0.0300374766" />
      </geometry>
      <material name="spoke_steel" />
    </visual>
    <visual name="front_wheel_spoke_02">
      <origin xyz="0.013858193 -0.00075 0.00574025149" rpy="1.17861399 0 1.62486319" />
      <geometry>
        <mesh filename="meshes/unit_cylinder_z.stl" scale="0.001 0.001 0.0300374766" />
      </geometry>
      <material name="spoke_steel" />
    </visual>
    <visual name="front_wheel_spoke_03">
      <origin xyz="0.0106066017 0.00075 0.0106066017" rpy="0.786645047 0 1.50020315" />
      <geometry>
        <mesh filename="meshes/unit_cylinder_z.stl" scale="0.001 0.001 0.0300374766" />
      </geometry>
      <material name="spoke_steel" />
    </visual>
    <visual name="front_wheel_spoke_04">
      <origin xyz="0.00574025149 -0.00075 0.013858193" rpy="-0.392182339 -0.0540668651 -1.57079633" />
      <geometry>
        <mesh filename="meshes/unit_cylinder_z.stl" scale="0.001 0.001 0.0300374766" />
      </geometry>
      <material name="spoke_steel" />
    </visual>
    <visual name="front_wheel_spoke_05">
      <origin xyz="0 0.00075 0.015" rpy="0 0.0499583957 -1.57079633" />
      <geometry>
        <mesh filename="meshes/unit_cylinder_z.stl" scale="0.001 0.001 0.0300374766" />
      </geometry>
      <material name="spoke_steel" />
    </visual>
    <visual name="front_wheel_spoke_06">
      <origin xyz="-0.00574025149 -0.00075 0.013858193" rpy="0.392182339 -0.0540668651 -1.57079633" />
      <geometry>
        <mesh filename="meshes/unit_cylinder_z.stl" scale="0.001 0.001 0.0300374766" />
      </geometry>
      <material name="spoke_steel" />
    </visual>
    <visual name="front_wheel_spoke_07">
      <origin xyz="-0.0106066017 0.00075 0.0106066017" rpy="0.786645047 0 -1.50020315" />
      <geometry>
        <mesh filename="meshes/unit_cylinder_z.stl" scale="0.001 0.001 0.0300374766" />
      </geometry>
      <material name="spoke_steel" />
    </visual>
    <visual name="front_wheel_spoke_08">
      <origin xyz="-0.013858193 -0.00075 0.00574025149" rpy="1.17861399 0 -1.62486319" />
      <geometry>
        <mesh filename="meshes/unit_cylinder_z.stl" scale="0.001 0.001 0.0300374766" />
      </geometry>
      <material name="spoke_steel" />
    </visual>
    <visual name="front_wheel_spoke_09">
      <origin xyz="-0.015 0.00075 0" rpy="1.57079633 0 -1.52083793" />
      <geometry>
        <mesh filename="meshes/unit_cylinder_z.stl" scale="0.001 0.001 0.0300374766" />
      </geometry>
      <material name="spoke_steel" />
    </visual>
    <visual name="front_wheel_spoke_10">
      <origin xyz="-0.013858193 -0.00075 -0.00574025149" rpy="1.96297867 0 -1.62486319" />
      <geometry>
        <mesh filename="meshes/unit_cylinder_z.stl" scale="0.001 0.001 0.0300374766" />
      </geometry>
      <material name="spoke_steel" />
    </visual>
    <visual name="front_wheel_spoke_11">
      <origin xyz="-0.0106066017 0.00075 -0.0106066017" rpy="2.35494761 0 -1.50020315" />
      <geometry>
        <mesh filename="meshes/unit_cylinder_z.stl" scale="0.001 0.001 0.0300374766" />
      </geometry>
      <material name="spoke_steel" />
    </visual>
    <visual name="front_wheel_spoke_12">
      <origin xyz="-0.00574025149 -0.00075 -0.013858193" rpy="-2.74941031 -0.0540668651 1.57079633" />
      <geometry>
        <mesh filename="meshes/unit_cylinder_z.stl" scale="0.001 0.001 0.0300374766" />
      </geometry>
      <material name="spoke_steel" />
    </visual>
    <visual name="front_wheel_spoke_13">
      <origin xyz="0 0.00075 -0.015" rpy="-3.14159265 0.0499583957 1.57079633" />
      <geometry>
        <mesh filename="meshes/unit_cylinder_z.stl" scale="0.001 0.001 0.0300374766" />
      </geometry>
      <material name="spoke_steel" />
    </visual>
    <visual name="front_wheel_spoke_14">
      <origin xyz="0.00574025149 -0.00075 -0.013858193" rpy="2.74941031 -0.0540668651 1.57079633" />
      <geometry>
        <mesh filename="meshes/unit_cylinder_z.stl" scale="0.001 0.001 0.0300374766" />
      </geometry>
      <material name="spoke_steel" />
    </visual>
    <visual name="front_wheel_spoke_15">
      <origin xyz="0.0106066017 0.00075 -0.0106066017" rpy="2.35494761 0 1.50020315" />
      <geometry>
        <mesh filename="meshes/unit_cylinder_z.stl" scale="0.001 0.001 0.0300374766" />
      </geometry>
      <material name="spoke_steel" />
    </visual>
    <visual name="front_wheel_spoke_16">
      <origin xyz="0.013858193 -0.00075 -0.00574025149" rpy="1.96297867 0 1.62486319" />
      <geometry>
        <mesh filename="meshes/unit_cylinder_z.stl" scale="0.001 0.001 0.0300374766" />
      </geometry>
      <material name="spoke_steel" />
    </visual>
    <collision>
      <origin xyz="0 0 0" rpy="-1.57079633 0 0" />
      <geometry><cylinder radius="0.044" length="0.012" /></geometry>
    </collision>
  </link>
  <link name="pedal_cycle_link">
    <inertial>
      <origin xyz="0 0 0" rpy="0 0 0" />
      <mass value="0.04" />
      <inertia ixx="4e-06" ixy="0" ixz="0" iyy="4e-06" iyz="0" izz="4e-06" />
    </inertial>
    <visual name="left_crank_arm">
      <origin xyz="0 -0.006 -0.01" rpy="2.60117315 0 0" />
      <geometry>
        <mesh filename="meshes/unit_cylinder_z.stl" scale="0.0024 0.0024 0.0233238076" />
      </geometry>
      <material name="spoke_steel" />
    </visual>
    <visual name="left_pedal_pad">
      <origin xyz="0 -0.012 -0.02" rpy="0 0 0" />
      <geometry>
        <mesh filename="meshes/unit_box.stl" scale="0.017 0.004 0.004" />
      </geometry>
      <material name="rubber_black" />
    </visual>
    <visual name="left_pedal_axle">
      <origin xyz="0 -0.011 -0.02" rpy="1.57079633 0 0" />
      <geometry>
        <mesh filename="meshes/unit_cylinder_z.stl" scale="0.0015 0.0015 0.012" />
      </geometry>
      <material name="spoke_steel" />
    </visual>
    <collision>
      <origin xyz="0 -0.006 -0.014" rpy="0 0 0" />
      <geometry><box size="0.02 0.03 0.034" /></geometry>
    </collision>
  </link>
  <link name="opposite_crank_link">
    <inertial>
      <origin xyz="0 0 0" rpy="0 0 0" />
      <mass value="0.04" />
      <inertia ixx="4e-06" ixy="0" ixz="0" iyy="4e-06" iyz="0" izz="4e-06" />
    </inertial>
    <visual name="right_crank_arm">
      <origin xyz="0 0.006 -0.01" rpy="2.60117315 0 3.14159265" />
      <geometry>
        <mesh filename="meshes/unit_cylinder_z.stl" scale="0.0024 0.0024 0.0233238076" />
      </geometry>
      <material name="spoke_steel" />
    </visual>
    <visual name="right_pedal_pad">
      <origin xyz="0 0.012 -0.02" rpy="0 0 0" />
      <geometry>
        <mesh filename="meshes/unit_box.stl" scale="0.017 0.004 0.004" />
      </geometry>
      <material name="rubber_black" />
    </visual>
    <visual name="right_pedal_axle">
      <origin xyz="0 0.011 -0.02" rpy="1.57079633 0 3.14159265" />
      <geometry>
        <mesh filename="meshes/unit_cylinder_z.stl" scale="0.0015 0.0015 0.012" />
      </geometry>
      <material name="spoke_steel" />
    </visual>
    <collision>
      <origin xyz="0 0.006 -0.014" rpy="0 0 0" />
      <geometry><box size="0.02 0.03 0.034" /></geometry>
    </collision>
  </link>
  <link name="pelican_body_link">
    <inertial>
      <origin xyz="0 0 0" rpy="0 0 0" />
      <mass value="0.45" />
      <inertia ixx="4.5e-05" ixy="0" ixz="0" iyy="4.5e-05" iyz="0" izz="4.5e-05" />
    </inertial>
    <visual name="round_body">
      <origin xyz="0 0 0" rpy="0 0 0" />
      <geometry>
        <mesh filename="meshes/unit_sphere.stl" scale="0.048 0.03 0.058" />
      </geometry>
      <material name="pelican_white" />
    </visual>
    <visual name="chest_belly">
      <origin xyz="0.013 0 -0.008" rpy="0 0 0" />
      <geometry>
        <mesh filename="meshes/unit_sphere.stl" scale="0.036 0.026 0.04" />
      </geometry>
      <material name="pelican_white" />
    </visual>
    <visual name="left_wing">
      <origin xyz="-0.01 -0.014 0" rpy="0 0 0" />
      <geometry>
        <mesh filename="meshes/unit_sphere.stl" scale="0.036 0.006 0.05" />
      </geometry>
      <material name="wing_gray" />
    </visual>
    <visual name="right_wing">
      <origin xyz="-0.01 0.014 0" rpy="0 0 0" />
      <geometry>
        <mesh filename="meshes/unit_sphere.stl" scale="0.036 0.006 0.05" />
      </geometry>
      <material name="wing_gray" />
    </visual>
    <visual name="left_wing_tip">
      <origin xyz="-0.023 -0.017 -0.016" rpy="0 0 0" />
      <geometry>
        <mesh filename="meshes/unit_sphere.stl" scale="0.02 0.004 0.018" />
      </geometry>
      <material name="feather_dark" />
    </visual>
    <visual name="right_wing_tip">
      <origin xyz="-0.023 0.017 -0.016" rpy="0 0 0" />
      <geometry>
        <mesh filename="meshes/unit_sphere.stl" scale="0.02 0.004 0.018" />
      </geometry>
      <material name="feather_dark" />
    </visual>
    <visual name="lower_neck">
      <origin xyz="0.015 0 0.0295" rpy="0.876058051 0 1.57079633" />
      <geometry>
        <mesh filename="meshes/unit_cylinder_z.stl" scale="0.01 0.01 0.023430749" />
      </geometry>
      <material name="pelican_white" />
    </visual>
    <visual name="head">
      <origin xyz="0.04 0 0.041" rpy="0 0 0" />
      <geometry>
        <mesh filename="meshes/unit_sphere.stl" scale="0.022 0.017 0.02" />
      </geometry>
      <material name="pelican_white" />
    </visual>
    <visual name="upper_bill">
      <origin xyz="0.068 0 0.041" rpy="1.57079633 0 1.57079633" />
      <geometry>
        <mesh filename="meshes/unit_cone_z.stl" scale="0.01 0.0145 0.038" />
      </geometry>
      <material name="bill_yellow" />
    </visual>
    <visual name="lower_bill_pouch">
      <origin xyz="0.064 0 0.032" rpy="0 0 0" />
      <geometry>
        <mesh filename="meshes/unit_sphere.stl" scale="0.046 0.014 0.014" />
      </geometry>
      <material name="pouch_orange" />
    </visual>
    <visual name="left_eye">
      <origin xyz="0.043 -0.008 0.045" rpy="0 0 0" />
      <geometry>
        <mesh filename="meshes/unit_sphere.stl" scale="0.003 0.0015 0.003" />
      </geometry>
      <material name="eye_black" />
    </visual>
    <visual name="right_eye">
      <origin xyz="0.043 0.008 0.045" rpy="0 0 0" />
      <geometry>
        <mesh filename="meshes/unit_sphere.stl" scale="0.003 0.0015 0.003" />
      </geometry>
      <material name="eye_black" />
    </visual>
    <visual name="head_crest">
      <origin xyz="0.032 0 0.052" rpy="0 0 0" />
      <geometry>
        <mesh filename="meshes/unit_sphere.stl" scale="0.008 0.008 0.01" />
      </geometry>
      <material name="pelican_white" />
    </visual>
    <visual name="short_tail">
      <origin xyz="-0.027 0 -0.012" rpy="0 0 0" />
      <geometry>
        <mesh filename="meshes/unit_sphere.stl" scale="0.02 0.012 0.01" />
      </geometry>
      <material name="feather_dark" />
    </visual>
    <collision>
      <origin xyz="0 0 0" rpy="0 0 0" />
      <geometry><sphere radius="0.03" /></geometry>
    </collision>
  </link>
  <link name="left_thigh_link">
    <inertial>
      <origin xyz="0 0 0" rpy="0 0 0" />
      <mass value="0.025" />
      <inertia ixx="2.5e-06" ixy="0" ixz="0" iyy="2.5e-06" iyz="0" izz="2.5e-06" />
    </inertial>
    <visual name="left_thigh_orange_segment">
      <origin xyz="0 0 -0.0107313694" rpy="3.14159265 0 1.57079633" />
      <geometry>
        <mesh filename="meshes/unit_cylinder_z.stl" scale="0.004 0.004 0.0214627388" />
      </geometry>
      <material name="leg_orange" />
    </visual>
    <collision>
      <origin xyz="0 0 -0.0107313694" rpy="0 0 0" />
      <geometry><cylinder radius="0.0025" length="0.0214627388" /></geometry>
    </collision>
  </link>
  <link name="left_shank_link">
    <inertial>
      <origin xyz="0 0 0" rpy="0 0 0" />
      <mass value="0.025" />
      <inertia ixx="2.5e-06" ixy="0" ixz="0" iyy="2.5e-06" iyz="0" izz="2.5e-06" />
    </inertial>
    <visual name="left_shank_orange_segment">
      <origin xyz="0 0 -0.01" rpy="3.14159265 0 1.57079633" />
      <geometry>
        <mesh filename="meshes/unit_cylinder_z.stl" scale="0.004 0.004 0.02" />
      </geometry>
      <material name="leg_orange" />
    </visual>
    <visual name="left_shank_webbed_foot">
      <origin xyz="0 -0.006 -0.02" rpy="0 0 0" />
      <geometry>
        <mesh filename="meshes/unit_sphere.stl" scale="0.017 0.007 0.004" />
      </geometry>
      <material name="leg_orange" />
    </visual>
    <collision>
      <origin xyz="0 0 -0.01" rpy="0 0 0" />
      <geometry><cylinder radius="0.0024" length="0.02" /></geometry>
    </collision>
  </link>
  <link name="right_thigh_link">
    <inertial>
      <origin xyz="0 0 0" rpy="0 0 0" />
      <mass value="0.025" />
      <inertia ixx="2.5e-06" ixy="0" ixz="0" iyy="2.5e-06" iyz="0" izz="2.5e-06" />
    </inertial>
    <visual name="right_thigh_orange_segment">
      <origin xyz="0 0 -0.0137132203" rpy="3.14159265 0 1.57079633" />
      <geometry>
        <mesh filename="meshes/unit_cylinder_z.stl" scale="0.004 0.004 0.0274264407" />
      </geometry>
      <material name="leg_orange" />
    </visual>
    <collision>
      <origin xyz="0 0 -0.0137132203" rpy="0 0 0" />
      <geometry><cylinder radius="0.0025" length="0.0274264407" /></geometry>
    </collision>
  </link>
  <link name="right_shank_link">
    <inertial>
      <origin xyz="0 0 0" rpy="0 0 0" />
      <mass value="0.025" />
      <inertia ixx="2.5e-06" ixy="0" ixz="0" iyy="2.5e-06" iyz="0" izz="2.5e-06" />
    </inertial>
    <visual name="right_shank_orange_segment">
      <origin xyz="0 0 -0.01" rpy="3.14159265 0 1.57079633" />
      <geometry>
        <mesh filename="meshes/unit_cylinder_z.stl" scale="0.004 0.004 0.02" />
      </geometry>
      <material name="leg_orange" />
    </visual>
    <visual name="right_shank_webbed_foot">
      <origin xyz="0 0.006 -0.02" rpy="0 0 0" />
      <geometry>
        <mesh filename="meshes/unit_sphere.stl" scale="0.017 0.007 0.004" />
      </geometry>
      <material name="leg_orange" />
    </visual>
    <collision>
      <origin xyz="0 0 -0.01" rpy="0 0 0" />
      <geometry><cylinder radius="0.0024" length="0.02" /></geometry>
    </collision>
  </link>
  <joint name="world_to_bike_frame" type="fixed">
    <origin xyz="0 0 0" rpy="0 0 0" />
    <parent link="world" />
    <child link="bike_frame_link" />
  </joint>
  <joint name="rear_wheel_spin_joint" type="continuous">
    <origin xyz="-0.055 0 0.044" rpy="0 0 0" />
    <parent link="bike_frame_link" />
    <child link="rear_wheel_link" />
    <axis xyz="0 1 0" />
    <mimic joint="pedal_cycle_joint" multiplier="-3.2" offset="0" />
  </joint>
  <joint name="front_wheel_spin_joint" type="continuous">
    <origin xyz="0.055 0 0.044" rpy="0 0 0" />
    <parent link="bike_frame_link" />
    <child link="front_wheel_link" />
    <axis xyz="0 1 0" />
    <mimic joint="pedal_cycle_joint" multiplier="-3.2" offset="0" />
  </joint>
  <joint name="pedal_cycle_joint" type="continuous" default_deg="25">
    <origin xyz="0 0 0.049" rpy="0 0 0" />
    <parent link="bike_frame_link" />
    <child link="pedal_cycle_link" />
    <axis xyz="0 1 0" />
  </joint>
  <joint name="opposite_crank_mimic_joint" type="continuous">
    <origin xyz="0 0 0.049" rpy="0 0 0" />
    <parent link="bike_frame_link" />
    <child link="opposite_crank_link" />
    <axis xyz="0 1 0" />
    <mimic joint="pedal_cycle_joint" multiplier="1" offset="3.14159265" />
  </joint>
  <joint name="pelican_body_fixed_joint" type="fixed">
    <origin xyz="-0.012 0 0.12" rpy="0 0 0" />
    <parent link="bike_frame_link" />
    <child link="pelican_body_link" />
  </joint>
  <joint name="left_hip_pedal_mimic_joint" type="continuous">
    <origin xyz="0.007567263 -0.006 -0.05" rpy="0 0 0" />
    <parent link="pelican_body_link" />
    <child link="left_thigh_link" />
    <axis xyz="0 1 0" />
    <mimic joint="pedal_cycle_joint" multiplier="0" offset="-0.208028951" />
  </joint>
  <joint name="left_knee_pedal_mimic_joint" type="continuous">
    <origin xyz="0 0 -0.0214627388" rpy="0 0 0" />
    <parent link="left_thigh_link" />
    <child link="left_shank_link" />
    <axis xyz="0 1 0" />
    <mimic joint="pedal_cycle_joint" multiplier="1" offset="0.208028951" />
  </joint>
  <joint name="right_hip_pedal_mimic_joint" type="continuous">
    <origin xyz="0.0087451063 0.006 -0.0437673851" rpy="0 0 0" />
    <parent link="pelican_body_link" />
    <child link="right_thigh_link" />
    <axis xyz="0 1 0" />
    <mimic joint="pedal_cycle_joint" multiplier="0" offset="-0.118957581" />
  </joint>
  <joint name="right_knee_pedal_mimic_joint" type="continuous">
    <origin xyz="0 0 -0.0274264407" rpy="0 0 0" />
    <parent link="right_thigh_link" />
    <child link="right_shank_link" />
    <axis xyz="0 1 0" />
    <mimic joint="pedal_cycle_joint" multiplier="1" offset="3.26055023" />
  </joint>
</robot>
